Workbook

Sheet Raw Data
A1: Timestamp | B1: How old are you? | C1: Did you find the diary? | D1: Did you find the option to change the owl's color? | E1: Did the controls in the game (buttons, text, images) feel crowded? | F1: Are color customizations well seperated from other controls or objects? (like the gift or the owl) | G1: Are color customizations ordered logically? | H1: If you chose "No" at the previous question, how would you improve the ordering of the customizations? | I1: Is it easy to navigate through the game? | J1: If you chose "No" at the previous question, please explain why. | K1: Do you have suggestions to improve the layout of the game? | L1: How did you feel when writing a diary entry? | M1: How did you feel when you read previously written diary entries? | N1: How did sending a message make you feel? | O1: How did receiving a message make you feel? | P1: Did the music of the game affect your mood? | Q1: If the music of the game affected your mood, how did it affect your mood? | R1: What would you change about the music? | S1: How do the colors used in the game make you feel? | T1: Did communicating with the owl feel comfortable? | U1: Why did communicating with the owl (not) feel comfortable? | V1: Did the message options feel relatable? | W1: Why did the message options (not) feel relatable? | X1: Are the three emoticons enough to show how you felt that day? | Y1: If you chose "No" at the previous question, please explain why. | Z1: What do you think about the concept of sending and receiving messages? | AA1: What is your opinion about writing diary entries? | AB1: What do you think about the music used in the game? | AC1: What is your opinion about the concept of receiving, sending, and using stickers?
A2: 44579.47 | B2: 15 | C2: Yes | D2: Yes | E2: 5 | F2: Yes | G2: Yes | I2: Yes | L2: Happy | M2: Nostalgic | N2: Comfortable | O2: Happy | P2: Yes | Q2: Positively | S2: Safe | T2: Yes | U2: It suited my expectations | V2: Yes | W2: I could find my problem | X2: Yes
A3: 44579.493 | B3: I prefer not to say | C3: No | D3: No | E3: 10 | F3: No | G3: No | H3: Make it a grayscale | I3: No | J3: It's crowded | K3: Less buttons | L3: anxious happy relieved | M3: anxious disturbed | N3: not safe exposed | O3: excited | P3: No | R3: Make it more happy | S3: like a child | T3: No | U3: i didn't connect | V3: No | W3: i couldn't find mine | X3: No | Y3: It wasn't enough | Z3: Kinda lame | AA3: It is boring | AB3: boring as well | AC3: dull

Sheet Data for Processing
A1: Raw Data
A2: Response count | E2: =COUNTA('Raw Data'!A:A) - 1 -> 2
A4: Age
A5: Count | C5: < 12 | E5: =COUNTIF('Raw Data'!B:B,"Younger than 12 years old") -> 0
C6: 12 | E6: =COUNTIF('Raw Data'!B:B,"12") -> 0
C7: 13 | E7: =COUNTIF('Raw Data'!B:B,"13") -> 0
C8: 14 | E8: =COUNTIF('Raw Data'!B:B,"14") -> 0
C9: 15 | E9: =COUNTIF('Raw Data'!B:B,"15") -> 1
C10: 16 | E10: =COUNTIF('Raw Data'!B:B,"16") -> 0
C11: 17 | E11: =COUNTIF('Raw Data'!B:B,"17") -> 0
C12: 18 | E12: =COUNTIF('Raw Data'!B:B,"18") -> 0
C13: > 18 | E13: =COUNTIF('Raw Data'!B:B,"Older than 18 years old") -> 0
C14: Prefer not to say | E14: =COUNTIF('Raw Data'!B:B,"I prefer not to say") -> 1
A15: Age * count | C15: < 12 | E15: -
C16: 12 | E16: =E6*C6 -> 0
C17: 13 | E17: =E7*C7 -> 0
C18: 14 | E18: =E8*C8 -> 0
C19: 15 | E19: =E9*C9 -> 15
C20: 16 | E20: =E10*C10 -> 0
C21: 17 | E21: =E11*C11 -> 0
C22: 18 | E22: =E12*C12 -> 0
C23: > 18 | E23: -
C24: Prefer not to say | E24: -

Sheet Processed Responses
A1: Processed Responses
A2: General
A3: Amount of responses | I3: ='Data for Processing'!E2 -> 2
A4: Age chart | J4: See chart
A5: Average age | I5: {=INDEX('Data for Processing'!C6:C12,MATCH(ROUND(AVERAGE(_xlfn._xlws.FILTER('Raw Data'!B:B,'Raw Data'!B:B > 0)),0),'Data for Processing'!C6:C12,0))} -> 15
A6: Median age | I6: =MEDIAN('Raw Data'!B:B) -> 15
A18: Layout
A19: Found diary | H19: Yes | I19: =COUNTIF('Raw Data'!C:C,"Yes") -> 1 | J19: See chart
H20: No | I20: =COUNTIF('Raw Data'!C:C,"No") -> 1
A22: Found color customization | H22: Yes | I22: =COUNTIF('Raw Data'!D:D,"Yes") -> 1 | J22: See chart
H23: No | I23: =COUNTIF('Raw Data'!D:D,"No") -> 1
A25: Did controls feel crowded? | H25: 0 - crowded | I25: =COUNTIF('Raw Data'!E:E,0) -> 0 | J25: See chart
H26: 1 | I26: =COUNTIF('Raw Data'!E:E,1) -> 0
H27: 2 | I27: =COUNTIF('Raw Data'!E:E,2) -> 0
H28: 3 | I28: =COUNTIF('Raw Data'!E:E,3) -> 0
H29: 4 | I29: =COUNTIF('Raw Data'!E:E,4) -> 0
H30: 5 | I30: =COUNTIF('Raw Data'!E:E,5) -> 1
H31: 6 | I31: =COUNTIF('Raw Data'!E:E,6) -> 0
H32: 7 | I32: =COUNTIF('Raw Data'!E:E,7) -> 0
H33: 8 | I33: =COUNTIF('Raw Data'!E:E,8) -> 0
H34: 9 | I34: =COUNTIF('Raw Data'!E:E,9) -> 0
H35: 10 - not crowded | I35: =COUNTIF('Raw Data'!E:E,10) -> 1
A37: Are color customizations well seperated from other controls or objects? | H37: Yes | I37: =COUNTIF('Raw Data'!F:F,"Yes") -> 1 | J37: See chart
H38: No | I38: =COUNTIF('Raw Data'!F:F,"No") -> 1
H39: Not seen | I39: =COUNTIF('Raw Data'!F:F,"I did not see color customizations") -> 0
A41: Are color customications ordered logically? | H41: Yes | I41: =COUNTIF('Raw Data'!G:G,"Yes") -> 1 | J41: See chart
H42: No | I42: =COUNTIF('Raw Data'!G:G,"No") -> 1
H43: Not seen | I43: =COUNTIF('Raw Data'!G:G,"I did not see color customizations") -> 0
A45: Is it easy to navigate through the game? | H45: Yes | I45: =COUNTIF('Raw Data'!I:I,"Yes") -> 1 | J45: See chart
H46: No | I46: =COUNTIF('Raw Data'!I:I,"No") -> 1
A52: Mood
A53: Did the music of the game affect the player's mood? | H53: Yes | I53: =COUNTIF('Raw Data'!P:P,"Yes") -> 1 | J53: See chart
H54: No | I54: =COUNTIF('Raw Data'!P:P,"No") -> 1
A56: Did communicating with the owl feel comfortable? | H56: Yes | I56: =COUNTIF('Raw Data'!T:T,"Yes") -> 1 | J56: See chart
H57: No | I57: =COUNTIF('Raw Data'!T:T,"No") -> 1
A68: Messages
A69: Did the message options feel relatable? | H69: Yes | I69: =COUNTIF('Raw Data'!V:V,"Yes") -> 1 | J69: See chart
H70: No | I70: =COUNTIF('Raw Data'!V:V,"No") -> 1
A84: Diary
A85: Are three emoticons enough? | H85: Yes | I85: =COUNTIF('Raw Data'!X:X,"Yes") -> 1 | J85: See chart
...
